<?xml version="1.0"?>
<!--
  Copyright 2015 Fadri Furrer, ASL, ETH Zurich, Switzerland
  Copyright 2015 Michael Burri, ASL, ETH Zurich, Switzerland
  Copyright 2015 Mina Kamel, ASL, ETH Zurich, Switzerland
  Copyright 2015 Janosch Nikolic, ASL, ETH Zurich, Switzerland
  Copyright 2015 Markus Achtelik, ASL, ETH Zurich, Switzerland

  Licensed under the Apache License, Version 2.0 (the "License");
  you may not use this file except in compliance with the License.
  You may obtain a copy of the License at

  http://www.apache.org/licenses/LICENSE-2.0

  Unless required by applicable law or agreed to in writing, software
  distributed under the License is distributed on an "AS IS" BASIS,
  WITHOUT WARRANTIES OR CONDITIONS OF ANY KIND, either express or implied.
  See the License for the specific language governing permissions and
  limitations under the License.
-->

<robot xmlns:xacro="http://ros.org/wiki/xacro">
  <!-- Macro for the inertia of a box -->
  <xacro:macro name="box_inertia" params="x y z mass">
    <inertia ixx="${0.0833333 * mass * (y*y + z*z)}" ixy="0.0" ixz="0.0"
      iyy="${0.0833333 * mass * (x*x + z*z)}" iyz="0.0"
      izz="${0.0833333 * mass * (x*x + y*y)}" />
  </xacro:macro>

  <!-- Macro for the inertial properties of a box -->
  <xacro:macro name="box_inertial" params="x y z mass *origin">
    <inertial>
      <mass value="${mass}" />
      <xacro:insert_block name="origin" />
      <xacro:box_inertia x="${x}" y="${y}" z="${z}" mass="${mass}" />
    </inertial>
  </xacro:macro>

  <!-- Main multirotor link -->
  <xacro:macro name="multirotor_base_macro"
    params="robot_namespace mass body_width body_height use_mesh_file mesh_file *inertia">
    <link name="${robot_namespace}/base_link"></link>

    <joint name="${robot_namespace}/base_joint" type="fixed">
      <origin xyz="0 0 0" rpy="0 0 0" />
      <parent link="${robot_namespace}/base_link" />
      <child link="${robot_namespace}/base_link_inertia" />
    </joint>

    <link name="${robot_namespace}/base_link_inertia">
      <inertial>
        <mass value="${mass}" />  <!-- [kg] -->
        <origin xyz="0 0 0" />
        <xacro:insert_block name="inertia" />
      </inertial>

      <visual>
        <origin xyz="0 0 0" rpy="0 0 0" />
        <geometry>
          <xacro:if value="${use_mesh_file}">
            <mesh filename="${mesh_file}" scale="1 1 1" />
          </xacro:if>
          <xacro:unless value="${use_mesh_file}">
            <box size="${body_width} ${body_width} ${body_height}"/> <!-- [m] [m] [m] -->
          </xacro:unless>
        </geometry>
      </visual>

      <collision>
        <origin xyz="0 0 0" rpy="0 0 0" />
        <geometry>
          <box size="${body_width} ${body_width} ${body_height}" /> <!-- [m] [m] [m] -->
        </geometry>
      </collision>
    </link>

    <!-- attach multirotor_base_plugin to the base_link -->
    <gazebo>
      <plugin filename="librotors_gazebo_multirotor_base_plugin.so" name="multirotor_base_plugin">
        <robotNamespace>${robot_namespace}</robotNamespace>
        <linkName>${robot_namespace}/base_link</linkName>
        <rotorVelocitySlowdownSim>${rotor_velocity_slowdown_sim}</rotorVelocitySlowdownSim>
      </plugin>
    </gazebo>
  </xacro:macro>

  <!--special link-->
  <xacro:macro name="special"
    params="child0 child1 child2 child3">

    {%- set pi = 3.141592 -%}
    {%- set ball_r = 0.001 -%}
    {%- set ball_m = 0.0001 -%}
    {%- set cyl_r = 0.001 -%}
    {%- set cyl_l = 0.03 -%}
    {%- set cyl_m = 0.0005 -%}
    {%- set jun_m = 0.0005 -%}
    {%- set jun_r = 0.0005 -%}
    {%- set box_m = 1.0 -%}
    {%- set box_x = 0.6 -%}
    {%- set box_y = 0.3 -%}
    {%- set box_z = 0.3 -%}
    {%- set number_elements = 50 -%}


    <joint name="special_joint_0" type="fixed">
      <parent link="junta3_{{number_elements-1}}_0"/>
      <child link="${child0}"/>
      <origin rpy="0 0 0" xyz="0 0 0.01"/>
    </joint>

    <joint name="special_joint_1" type="fixed">
      <parent link="junta3_{{number_elements-1}}_1"/>
      <child link="${child1}"/>
      <origin rpy="0 0 0" xyz="0 0 0.01"/>
    </joint>

    <joint name="special_joint_2" type="fixed">
      <parent link="junta3_{{number_elements-1}}_2"/>
      <child link="${child2}"/>
      <origin rpy="0 0 0" xyz="0 0 0.01"/>
    </joint>

    <joint name="special_joint_3" type="fixed">
      <parent link="junta3_{{number_elements-1}}_3"/>
      <child link="${child3}"/>
      <origin rpy="0 0 0" xyz="0 0 0.01"/>
    </joint>

    <!-- tether_ball_link-->
    {%- macro tether_ball_link(n, direc) -%}
      <link name="link_ball_{{n}}_{{direc}}">
        <visual>
          <geometry>
            <sphere radius="{{ball_r}}"/>
          </geometry>
          <material name="black">
            <color rgba="0 0 0 1"/>
          </material>
        </visual>
        <collision>
          <geometry>
            <sphere radius="{{ball_r}}"/>
          </geometry>
        </collision>
        <inertial>
          <mass value="{{ball_m}}"/>
          {%- set ball_i = 2/5*ball_m*ball_r**2 -%}
          <inertia ixx="{{ball_i}}" iyy="{{ball_i}}" izz="{{ball_i}}" ixy="0" ixz="0" iyz="0"/>
        </inertial>
      </link>
    {%- endmacro -%}

    <!-- tether_cylinder_link-->
    {%- macro tether_cylinder_link(n, direc) -%}
      <link name="link_cylinder_{{n}}_{{direc}}">
        <visual>
          <geometry>
            <cylinder length="{{cyl_l}}" radius="{{cyl_r}}"/>
          </geometry>
          <material name="black">
            <color rgba="0 0 0 1"/>
          </material>
        </visual>
        <collision>
          <geometry>
            <cylinder length="{{cyl_l}}" radius="{{cyl_r}}"/>
          </geometry>
        </collision>
        <inertial>
          <mass value="{{cyl_m}}"/>
          {%- set cyl_i = 1/12*cyl_m*(3*cyl_r**2+cyl_l**2) -%}
          {%- set cyl_iz = 1/2*cyl_m*cyl_r**2 -%}
          <inertia ixx="{{cyl_i}}" iyy="{{cyl_i}}" izz="{{cyl_iz}}" ixy="0" ixz="0" iyz="0"/>
        </inertial>
      </link>
    {%- endmacro -%}


    <!--tether_ball_joint-->
    {%- macro tether_ball_joint(n, direc) -%}
      <joint name="joint_ball_{{n}}_{{direc}}" type="fixed">
        <parent link="link_cylinder_{{n-1}}_{{direc}}"/>
        <child link="link_ball_{{n}}_{{direc}}"/>
        {% if direc == 0 %}
        <origin rpy="-{{pi/2}} 0 0" xyz="0 0 -{{cyl_l/2}}"/>
        {% endif %}
        {% if direc == 1 %}
        <origin rpy="0 {{pi/2}} 0" xyz="0 0 -{{cyl_l/2}}"/>
        {% endif %}
        {% if direc == 2 %}
        <origin rpy="{{pi/2}} 0 0" xyz="0 0 -{{cyl_l/2}}"/>
        {% endif %}
        {% if direc == 3 %}
        <origin rpy="0 -{{pi/2}} 0" xyz="0 0 -{{cyl_l/2}}"/>
        {% endif %}
      </joint>
    {%- endmacro -%}


    <!--tether_cylinder_joint-->
    {%- macro tether_cylinder_joint(n, direc) -%}
      <link name="junta1_{{n}}_{{direc}}">
      {%- set jun_i = 2/5*ball_m*ball_r**2 -%}
        <inertial>
          <mass value="{{jun_m}}" />
          <!--<inertia ixx="{{jun_i}}" ixy="0" ixz="0" iyy="{{jun_i}}" iyz="0" izz="{{jun_i}}" />-->
          <inertia ixx="5.8083e-4" ixy="0" ixz="0" iyy="3.0833e-5" iyz="0" izz="5.9083e-4" />
        </inertial>
      </link>
      <link name="junta3_{{n}}_{{direc}}">
        <inertial>
          <mass value="{{jun_m}}" />
          <inertia ixx="5.8083e-4" ixy="0" ixz="0" iyy="3.0833e-5" iyz="0" izz="5.9083e-4" />
        </inertial>
      </link>
      <joint name="joint1_{{n}}_{{direc}}" type="continuous">
        <parent link="link_ball_{{n}}_{{direc}}"/>
        <child link="junta1_{{n}}_{{direc}}"/>
        <axis xyz="0 1 0" />
      </joint>
      <joint name="joint3_{{n}}_{{direc}}" type="continuous">
        <parent link="junta1_{{n}}_{{direc}}"/>
        <child link="junta3_{{n}}_{{direc}}"/>
        <axis xyz="1 0 0" />
      </joint>
      <joint name="jointfixed_{{n}}_{{direc}}" type="fixed">
        <parent link="junta3_{{n}}_{{direc}}"/>
        <child link="link_cylinder_{{n}}_{{direc}}"/>
        {% if direc == 0 %}
        <origin rpy="{{pi/2}} 0 0" xyz="0 {{cyl_l/2}} 0"/>
        {% endif %}
        {% if direc == 1 %}
        <origin rpy="0 -{{pi/2}} 0" xyz="{{cyl_l/2}} 0 0"/>
        {% endif %}
        {% if direc == 2 %}
        <origin rpy="-{{pi/2}} 0 0" xyz="0 -{{cyl_l/2}} 0"/>
        {% endif %}
        {% if direc == 3 %}
        <origin rpy="0 {{pi/2}} 0" xyz="-{{cyl_l/2}} 0 0"/>
        {% endif %}
      </joint>
    {%- endmacro -%}


    <!--base_component-->
      <link name="base_link">
        <visual>
          <geometry>
            <box size="{{box_x}} {{box_y}} {{box_z}}"/>
          </geometry>
          <material name="silver">
            <color rgba="0.75 0.75 0.75 1"/>
          </material>
        </visual>
        <collision>
          <geometry>
            <box size="{{box_x}} {{box_y}} {{box_z}}"/>
          </geometry>
        </collision>
        <inertial>
          <mass value="{{box_m}}"/>
          {%- set box_ix = 1/12*box_m*(box_y**2+box_z**2) -%}
          {%- set box_iy = 1/12*box_m*(box_x**2+box_z**2) -%}
          {%- set box_iz = 1/12*box_m*(box_x**2+box_y**2) -%}
          <inertia ixx="{{box_ix}}" iyy="{{box_iy}}" izz="{{box_iz}}" ixy="0" ixz="0" iyz="0"/>
        </inertial>
      </link>
    <!--base_ball_joint-->
      <joint name="joint_ball_0_0" type="fixed">
          <parent link="base_link"/>
          <child link="link_ball_0_0"/>
          <origin rpy="0 0 0" xyz="{{box_x/2}} {{box_y/2}} {{box_z/2}}"/>
      </joint>

      <joint name="joint_ball_0_1" type="fixed">
          <parent link="base_link"/>
          <child link="link_ball_0_1"/>
          <origin rpy="0 0 0" xyz="{{box_x/2}} -{{box_y/2}} {{box_z/2}}"/>
      </joint>
      <joint name="joint_ball_0_2" type="fixed">
          <parent link="base_link"/>
          <child link="link_ball_0_2"/>
          <origin rpy="0 0 0" xyz="-{{box_x/2}} -{{box_y/2}} {{box_z/2}}"/>
      </joint>
      <joint name="joint_ball_0_3" type="fixed">
          <parent link="base_link"/>
          <child link="link_ball_0_3"/>
          <origin rpy="0 0 0" xyz="-{{box_x/2}} {{box_y/2}} {{box_z/2}}"/>
      </joint>

      <!-- main-->
      {%- set direc = 0 -%}
      {% for direc in range(4)-%}
      {% for n in range(1,number_elements) -%}
      {{tether_ball_joint(n, direc)}}
      {% endfor -%}
      {% for n in range(0,number_elements) -%}
      {{tether_ball_link(n, direc)}}
      {{tether_cylinder_link(n, direc)}}
      {{tether_cylinder_joint(n, direc)}}
      {% endfor -%}
      {% endfor -%}
  </xacro:macro>

  <!--<xacro:include filename="$(find rotors_description)/urdf/tortoisebot.urdf" />-->
  <!-- Rotor joint and link -->
  <xacro:macro name="vertical_rotor"
    params="robot_namespace suffix direction motor_constant moment_constant parent mass_rotor radius_rotor time_constant_up time_constant_down max_rot_velocity motor_number rotor_drag_coefficient rolling_moment_coefficient color use_own_mesh mesh *origin *inertia">
    <joint name="${robot_namespace}/rotor_${motor_number}_joint" type="continuous">
      <xacro:insert_block name="origin" />
      <axis xyz="0 0 1" />
      <!-- TODO(ff): not currently set because it's not yet supported -->
      <!-- <limit effort="2000" velocity="${max_rot_velocity}" /> -->
      <parent link="${parent}" />
      <child link="${robot_namespace}/rotor_${motor_number}" />
    </joint>
    <link name="${robot_namespace}/rotor_${motor_number}">
      <inertial>
        <mass value="${mass_rotor}" /> <!-- [kg] -->
        <xacro:insert_block name="inertia" />
      </inertial>
      <visual>
        <geometry>
          <!-- <cylinder length="0.005" radius="${radius_rotor}"/> --> <!-- [m] -->
          <xacro:if value="${use_own_mesh}">
            <mesh filename="${mesh}"
              scale="1 1 1" />
          </xacro:if>
          <xacro:unless value="${use_own_mesh}">
            <mesh filename="package://rotors_description/meshes/propeller_${direction}.dae"
              scale="${radius_rotor} ${radius_rotor} ${radius_rotor}" /> <!-- The propeller meshes have a radius of 1m -->
            <!-- <box size="${2*radius_rotor} 0.01 0.005"/> -->
          </xacro:unless>
        </geometry>
      </visual>
      <collision>
        <geometry>
          <cylinder length="0.005" radius="${radius_rotor}" /> <!-- [m] -->
        </geometry>
      </collision>
    </link>
    <gazebo>
      <plugin name="${robot_namespace}_${suffix}_motor_model" filename="librotors_gazebo_motor_model.so">
        <robotNamespace>${robot_namespace}</robotNamespace>
        <jointName>${robot_namespace}/rotor_${motor_number}_joint</jointName>
        <linkName>${robot_namespace}/rotor_${motor_number}</linkName>
        <turningDirection>${direction}</turningDirection>
        <timeConstantUp>${time_constant_up}</timeConstantUp>
        <timeConstantDown>${time_constant_down}</timeConstantDown>
        <maxRotVelocity>${max_rot_velocity}</maxRotVelocity>
        <motorConstant>${motor_constant}</motorConstant>
        <momentConstant>${moment_constant}</momentConstant>
        <commandSubTopic>gazebo/command/motor_speed</commandSubTopic>
        <motorNumber>${motor_number}</motorNumber>
        <rotorDragCoefficient>${rotor_drag_coefficient}</rotorDragCoefficient>
        <rollingMomentCoefficient>${rolling_moment_coefficient}</rollingMomentCoefficient>
        <motorSpeedPubTopic>motor_speed/${motor_number}</motorSpeedPubTopic>
        <rotorVelocitySlowdownSim>${rotor_velocity_slowdown_sim}</rotorVelocitySlowdownSim>
      </plugin>
    </gazebo>
    <gazebo reference="${robot_namespace}/rotor_${motor_number}">
      <material>Gazebo/${color}</material>
    </gazebo>
  </xacro:macro>
</robot>
